Workbook

Sheet Property Summary
I2: Property Summary
B3: =C8&", "&C9 -> Phoenix, AZ | I3: Wind River Group
B5: Property Description | C5: CoStar Properties: Summary | E5: Property Size | F5: CoStar Properties: Summary | H5: Purchase Metrics | I5: OM / T12 Financials
B6: Property Name | C6: Serafina | E6: Total Units | F6: 183 | H6: Trailing 12 Revenue | I6: 3412780.9
B7: Street Address | C7: 11025 S 51st St | E7: Avg Unit Size | F7: 863 | H7: Trailing 12 Expenses | I7: 1245455.1
B8: City | C8: Phoenix | E8: Current Vacancy | F8: 0.055 | H8: Trailing 12 Net Operating Income | I8: =I6-I7 -> 2167325.8
B9: State | C9: AZ | E9: Building(s) | F9: 15
B10: County | C10: Maricopa | E10: Floors | F10: 2 | H10: Guidance Price | I10: 38000000
B11: Zip Code | C11: 85044 | H11: Implied Cap Rate | I11: =iferror(I8/I10,"") -> 0.057034889
B12: Land Area | C12: 8.15 | H12: Price per Unit | I12: =iferror(I10/F6,"") -> 207650.27
B13: Year Built | C13: 1985 | H13: Call for Offers Date
B14: Year Renovated
B15: Management Type | C15: 3rd Party Management
B16: Management Company | C16: Western Wealth Communities
B18: Seller Information
B19: Seller Name | C19: Western Wealth Capital
B20: How Long Have They Owned? | C20: 6
B21: Last Sold Price | C21: 27450000
B22: Why Are They Selling? | C22: "They want to take some chips off of the table", Brett Polachek
B23: What Improvements Have They Made? | C23: Classic – original 1980’s décor – 60 units Prior Upgrade (PU) - stainless or black appliances, dark grey cabinets, some with hardware, formica, no backsplash, new carpet & vinyl – 10 units Upgrade - backsplash, stainless steel appliances, hardware on cabinets, white cabinets, resurfaced counter tops, new vinyl & carpet, full paint – 111 units Elite - matte black accents/hardware, hardsurface, back splash, farmers sink, stainless steel appliances, full paint, new carpet & vinyl – 2 units
B24: What Matters Most to Them? | C24: Broker is not sure but they are firm on the $40 million, had offers for less and didn't take them.
B25: Brokers Name | C25: Brett Polachek
B26: Brokerage | C26: Newmark
B27: Broker's Email | C27: Brett.Polachek@nmrk.com
B28: Broker's Phone Number | C28: 602-952-3833

Sheet Demos
B2: Demos | G2: Property Rating Scorecard
B5: CoStar Properties: Demographics | C5: 1 Mile | D5: 3 Mile | E5: 5 Mile | G5: Multifamily Rating Scale | H5: Figure | I5: Score | J5: Weighting | K5: Increments | L5: 10 | M5: 9 | N5: 8 | O5: 7 | P5: 6 | Q5: 5 | R5: 4
B6: Population | C6: 9393 | D6: 100969 | E6: 250903 | G6: Population | H6: =D6 -> 100969 | I6: =ifs(H6>=L6,$L$5,and(H6<L6,H6>=M6),$M$5,and(H6<M6,H6>=N6),$N$5,and(H6<N6,H6>=O6),$O$5,and(H6<O6,H6>=P6),$P$5,and(H6<P6,H6>=Q6),$Q$5,H6<Q6,$R$5) -> 10 | J6: 0.075 | K6: 5000 | L6: =M6+$K6 -> 70000 | M6: =N6+$K6 -> 65000 | N6: 60000 | O6: =N6-$K6 -> 55000 | P6: =O6-$K6 -> 50000 | Q6: =P6-$K6 -> 45000
B7: Population Growth | C7: -0.003 | D7: -0.003 | E7: -0.003 | G7: Population Growth | H7: =D7 -> -0.003 | I7: =ifs(H7>=L7,$L$5,and(H7<L7,H7>=M7),$M$5,and(H7<M7,H7>=N7),$N$5,and(H7<N7,H7>=O7),$O$5,and(H7<O7,H7>=P7),$P$5,and(H7<P7,H7>=Q7),$Q$5,H7<Q7,$R$5) -> 4 | J7: 0.1 | K7: 0.0025 | L7: =M7+$K7 -> 0.01 | M7: =N7+$K7 -> 0.0075 | N7: 0.005 | O7: =N7-$K7 -> 0.0025 | P7: =O7-$K7 -> 0 | Q7: =P7-$K7 -> -0.0025
B8: Median HH Income | C8: 75362 | D8: 80544 | E8: 84222 | G8: Median HH Income | H8: =D8 -> 80544 | I8: =ifs(H8>=L8,$L$5,and(H8<L8,H8>=M8),$M$5,and(H8<M8,H8>=N8),$N$5,and(H8<N8,H8>=O8),$O$5,and(H8<O8,H8>=P8),$P$5,and(H8<P8,H8>=Q8),$Q$5,H8<Q8,$R$5) -> 10 | J8: 0.1 | K8: 5000 | L8: =M8+$K8 -> 70000 | M8: =N8+$K8 -> 65000 | N8: 60000 | O8: =N8-$K8 -> 55000 | P8: =O8-$K8 -> 50000 | Q8: =P8-$K8 -> 45000
B9: Median Home Value | C9: 345268 | D9: 386764 | E9: 389488 | G9: Median Home Value | H9: =D9 -> 386764 | I9: =ifs(H9>=L9,$L$5,and(H9<L9,H9>=M9),$M$5,and(H9<M9,H9>=N9),$N$5,and(H9<N9,H9>=O9),$O$5,and(H9<O9,H9>=P9),$P$5,and(H9<P9,H9>=Q9),$Q$5,H9<Q9,$R$5) -> 7 | J9: 0.075 | K9: 50000 | L9: =M9+$K9 -> 525000 | M9: =N9+$K9 -> 475000 | N9: 425000 | O9: =N9-$K9 -> 375000 | P9: =O9-$K9 -> 325000 | Q9: =P9-$K9 -> 275000
B10: Renter Households % | C10: 0.43 | D10: 0.48 | E10: 0.43 | G10: Renter Households % | H10: =D10 -> 0.48 | I10: =ifs(H10>=L10,$L$5,and(H10<L10,H10>=M10),$M$5,and(H10<M10,H10>=N10),$N$5,and(H10<N10,H10>=O10),$O$5,and(H10<O10,H10>=P10),$P$5,and(H10<P10,H10>=Q10),$Q$5,H10<Q10,$R$5) -> 9 | J10: 0.05 | K10: 0.05 | L10: =M10+$K10 -> 0.5 | M10: =N10+$K10 -> 0.45 | N10: 0.4 | O10: =N10-$K10 -> 0.35 | P10: =O10-$K10 -> 0.3 | Q10: =P10-$K10 -> 0.25
B11: Best Places | C11: Zip Code | D11: National Average | G11: Violent Crime Rate | H11: =C12 -> 37.5 | I11: =ifs(H11<=L11,$L$5,and(H11>L11,H11<=M11),$M$5,and(H11>M11,H11<=N11),$N$5,and(H11>N11,H11<=O11),$O$5,and(H11>O11,H11<=P11),$P$5,and(H11>P11,H11<=Q11),$Q$5,H11>Q11,$R$5) -> 6 | J11: 0.05 | K11: 5 | L11: =M11-$K11 -> 20 | M11: =N11-$K11 -> 25 | N11: 30 | O11: =N11+$K11 -> 35 | P11: =O11+$K11 -> 40 | Q11: =P11+$K11 -> 45
B12: Violent Crime Rate | C12: 37.5 | D12: 22.7 | G12: Property Crime Rate | H12: =C13 -> 52.8 | I12: =ifs(H12<=L12,$L$5,and(H12>L12,H12<=M12),$M$5,and(H12>M12,H12<=N12),$N$5,and(H12>N12,H12<=O12),$O$5,and(H12>O12,H12<=P12),$P$5,and(H12>P12,H12<=Q12),$Q$5,H12>Q12,$R$5) -> 5 | J12: 0.05 | K12: 5 | L12: =M12-$K12 -> 30 | M12: =N12-$K12 -> 35 | N12: 40 | O12: =N12+$K12 -> 45 | P12: =O12+$K12 -> 50 | Q12: =P12+$K12 -> 55
B13: Property Crime Rate | C13: 52.8 | D13: 35.4 | G13: School Ratings | H13: =E15 -> 4 | I13: =ifs(H13>=L13,$L$5,and(H13<L13,H13>=M13),$M$5,and(H13<M13,H13>=N13),$N$5,and(H13<N13,H13>=O13),$O$5,and(H13<O13,H13>=P13),$P$5,and(H13<P13,H13>=Q13),$Q$5,H13<Q13,$R$5) -> 5 | J13: 0.075 | K13: 1 | L13: =M13+$K13 -> 9 | M13: =N13+$K13 -> 8 | N13: 7 | O13: =N13-$K13 -> 6 | P13: =O13-$K13 -> 5 | Q13: =P13-$K13 -> 4
B14: Great Schools | C14: Elementary | D14: High School | G14: Walk Score | H14: =C17 -> 43 | I14: =ifs(H14>=L14,$L$5,and(H14<L14,H14>=M14),$M$5,and(H14<M14,H14>=N14),$N$5,and(H14<N14,H14>=O14),$O$5,and(H14<O14,H14>=P14),$P$5,and(H14<P14,H14>=Q14),$Q$5,H14<Q14,$R$5) -> 6 | J14: 0.075 | K14: 10 | L14: =M14+$K$14 -> 80 | M14: =N14+$K$14 -> 70 | N14: 60 | O14: =N14-$K$14 -> 50 | P14: =O14-$K$14 -> 40 | Q14: =P14-$K$14 -> 30
B15: School Ratings | C15: 4 | D15: 4 | E15: =iferror(average(C15:D15),"") -> 4 | G15: Transit Score | H15: =C18 -> 38 | I15: =ifs(H15>=L15,$L$5,and(H15<L15,H15>=M15),$M$5,and(H15<M15,H15>=N15),$N$5,and(H15<N15,H15>=O15),$O$5,and(H15<O15,H15>=P15),$P$5,and(H15<P15,H15>=Q15),$Q$5,H15<Q15,$R$5) -> 5 | J15: 0.075 | K15: 10 | L15: =M15+$K$15 -> 80 | M15: =N15+$K$15 -> 70 | N15: 60 | O15: =N15-$K$15 -> 50 | P15: =O15-$K$15 -> 40 | Q15: =P15-$K$15 -> 30
B16: CoStar Properties: Summary | G16: Submarket Vacancy | H16: =C20 -> 0.086 | I16: =ifs(H16<=L16,$L$5,and(H16>L16,H16<=M16),$M$5,and(H16>M16,H16<=N16),$N$5,and(H16>N16,H16<=O16),$O$5,and(H16>O16,H16<=P16),$P$5,and(H16>P16,H16<=Q16),$Q$5,H16>Q16,$R$5) -> 7 | J16: 0.1 | K16: 0.01 | L16: =M16-$K$16 -> 0.06 | M16: =N16-$K$16 -> 0.07 | N16: 0.08 | O16: =N16+$K$16 -> 0.09 | P16: =O16+$K$16 -> 0.1 | Q16: =P16+$K$16 -> 0.11
B17: Walk Score | C17: 43 | G17: Submarket Delivered % of Inventory | H17: =C23 -> 0.034245928 | I17: =ifs(H17<=L17,$L$5,and(H17>L17,H17<=M17),$M$5,and(H17>M17,H17<=N17),$N$5,and(H17>N17,H17<=O17),$O$5,and(H17>O17,H17<=P17),$P$5,and(H17>P17,H17<=Q17),$Q$5,H17>Q17,$R$5) -> 8 | J17: 0.1 | K17: 0.005 | L17: =M17-$K$17 -> 0.025 | M17: =N17-$K$17 -> 0.03 | N17: 0.035 | O17: =N17+$K17 -> 0.04 | P17: =O17+$K17 -> 0.045 | Q17: =P17+$K17 -> 0.05
B18: Transit Score | C18: 38 | G18: Submarket Construction % of Inventory | H18: =C25 -> 0.015973032 | I18: =ifs(H18<=L18,$L$5,and(H18>L18,H18<=M18),$M$5,and(H18>M18,H18<=N18),$N$5,and(H18>N18,H18<=O18),$O$5,and(H18>O18,H18<=P18),$P$5,and(H18>P18,H18<=Q18),$Q$5,H18>Q18,$R$5) -> 10 | J18: 0.075 | K18: 0.005 | L18: =M18-$K$18 -> 0.025 | M18: =N18-$K$18 -> 0.03 | N18: 0.035 | O18: =N18+$K18 -> 0.04 | P18: =O18+$K18 -> 0.045 | Q18: =P18+$K18 -> 0.05
B19: CoStar Properties: Analytics - Submarket | G19: Total | I19: =sumproduct(I6:I18,J6:J18) -> 7.125 | J19: =sum(J6:J18) -> 1
B20: Submarket Vacancy | C20: 0.086 | G20: Property Rating Decision | H20: =ifs(I19>=H22,G22,and(I19<H22,I19>=H23),G23,I19<H23,G24) -> Move Forward
B21: Submarket Inventory Units | C21: 31741
B22: Submarket 12 Mo Delivered Units | C22: 1087 | G22: Move Forward | H22: 7
B23: Submarket Delivered % of Inventory | C23: =iferror(C22/C21,"") -> 0.034245928 | G23: Quick Check with Team | H23: 5.5
B24: Submarket Under Construction Units | C24: 507 | G24: Don't Move Forward
B25: Submarket Construction % of Inventory | C25: =iferror(C24/C21,"") -> 0.015973032
B26: Submarket Cap Rate | C26: 0.047
B27: Submarket Sale Price / Unit | C27: 233000
B28: CoStar Properties: Analytics - Market
B29: Market Vacancy | C29: 0.115
B30: Market Inventory Units | C30: 408282
B31: Market 12 Mo Delivered Units | C31: 2450
B32: Market Delivered % of Inventory | C32: =iferror(C31/C30,"") -> 0.0060007544
B33: Market Under Construction Units | C33: 27188
B34: Market Construction % of Inventory | C34: =iferror(C33/C30,"") -> 0.066591229
B35: Market Cap Rate | C35: 0.049
B36: Market Sale Price / Unit | C36: 263000

Sheet Text Overview

Sheet Historical Financials
H2: Historical Financials
B3: ='Property Summary'!B3 -> Phoenix, AZ | H3: ='Property Summary'!I3 -> Wind River Group
B5: Total Units | C5: ='Unit Mix & Comps'!D34 -> 184
B6: Occupied Units | C6: ='Unit Mix & Comps'!E34 -> 169
B7: Occupancy % | C7: ='Unit Mix & Comps'!E35 -> 0.91847826
B9: Rental Income | C9: Trailing 12 | D9: Per Unit | E9: Trailing 6 | F9: Per Unit | G9: Trailing 3 | H9: Per Unit
B10: Potential Rental Income | C10: 3425241 | D10: =iferror(C10/$C$5,"") -> 18615.44 | E10: 0 | F10: =iferror(E10/$C$5,"") -> 0 | G10: 0 | H10: =iferror(G10/$C$5,"") -> 0
B11: Loss to Lease | C11: -246212 | D11: =iferror(-C11/C$10,"") -> 0.071881657 | E11: 0 | F11: =iferror(-E11/E$10,"") | G11: 0 | H11: =iferror(-G11/G$10,"")
A12: - | B12: Vacancy Loss | C12: -255589.29 | D12: =iferror(-C12/sum(C$10:C$11),"") -> 0.08039854 | E12: 0 | F12: =iferror(-E12/sum(E$10:E$11),"") | G12: 0 | H12: =iferror(-G12/sum(G$10:G$11),"")
A13: - | B13: Bad Debt Expense | C13: -42218.63 | D13: =iferror(-C13/sum(C$10:C$12),"") -> 0.014441423 | E13: 0 | F13: =iferror(-E13/sum(E$10:E$12),"") | G13: 0 | H13: =iferror(-G13/sum(G$10:G$12),"")
A14: - | B14: Concessions | C14: -53858.32 | D14: =iferror(-C14/sum(C$10:C$12),"") -> 0.018422928 | E14: 0 | F14: =iferror(-E14/sum(E$10:E$12),"") | G14: 0 | H14: =iferror(-G14/sum(G$10:G$12),"")
B15: Total Rental Income | C15: =sum(C10:C14) -> 2827362.8 | D15: =iferror(C15/$C$5,"") -> 15366.102 | E15: =sum(E10:E14) -> 0 | F15: =iferror(E15/$C$5,"") -> 0 | G15: =sum(G10:G14) -> 0 | H15: =iferror(G15/$C$5,"") -> 0
B16: Total RUBS Income | C16: 184233.56 | D16: =iferror(C16/$C$5,"") -> 1001.2693 | E16: 0 | F16: =iferror(E16/$C$5,"") -> 0 | G16: 0 | H16: =iferror(G16/$C$5,"") -> 0
B17: Total Other Income | C17: =508261.79-C16+1921.68+6459.85+11499.37+57275.42 -> 401184.55 | D17: =iferror(C17/$C$5,"") -> 2180.3508 | E17: 0 | F17: =iferror(E17/$C$5,"") -> 0 | G17: 0 | H17: =iferror(G17/$C$5,"") -> 0
B18: Total Revenue | C18: =sum(C15:C17) -> 3412780.9 | D18: =iferror(C18/$C$5,"") -> 18547.722 | E18: =sum(E15:E17) -> 0 | F18: =iferror(E18/$C$5,"") -> 0 | G18: =sum(G15:G17) -> 0 | H18: =iferror(G18/$C$5,"") -> 0
B20: Operating Expenses
B21: Total General & Admin | C21: 126768.37 | D21: =iferror(C21/$C$5,"") -> 688.95853 | E21: 0 | F21: =iferror(E21/$C$5,"") -> 0 | G21: 0 | H21: =iferror(G21/$C$5,"") -> 0
B22: Total Payroll | C22: 324615.54 | D22: =iferror(C22/$C$5,"") -> 1764.2149 | E22: 0 | F22: =iferror(E22/$C$5,"") -> 0 | G22: 0 | H22: =iferror(G22/$C$5,"") -> 0
B23: Total Leasing & Marketing | C23: 86807.36 | D23: =iferror(C23/$C$5,"") -> 471.77913 | E23: 0 | F23: =iferror(E23/$C$5,"") -> 0 | G23: 0 | H23: =iferror(G23/$C$5,"") -> 0
B24: Total Utilities | C24: 262578.11 | D24: =iferror(C24/$C$5,"") -> 1427.0549 | E24: 0 | F24: =iferror(E24/$C$5,"") -> 0 | G24: 0 | H24: =iferror(G24/$C$5,"") -> 0
B25: Total Repairs & Maintenance | C25: 55342.64 | D25: =iferror(C25/$C$5,"") -> 300.77522 | E25: 0 | F25: =iferror(E25/$C$5,"") -> 0 | G25: 0 | H25: =iferror(G25/$C$5,"") -> 0
B26: Total HOA Assessments | C26: 20329.82 | D26: =iferror(C26/$C$5,"") -> 110.48815 | E26: 0 | F26: =iferror(E26/$C$5,"") -> 0 | G26: 0 | H26: =iferror(G26/$C$5,"") -> 0
B27: Total Turnover Expense | C27: 22404.11 | D27: =iferror(C27/$C$5,"") -> 121.76147 | E27: 0 | F27: =iferror(E27/$C$5,"") -> 0 | G27: 0 | H27: =iferror(G27/$C$5,"") -> 0
B28: Total Contract Services | C28: =101374.9-55342.64 -> 46032.26 | D28: =iferror(C28/$C$5,"") -> 250.17533 | E28: 0 | F28: =iferror(E28/$C$5,"") -> 0 | G28: 0 | H28: =iferror(G28/$C$5,"") -> 0
B29: Total Insurance Expense | C29: 53468.94 | D29: =iferror(C29/$C$5,"") -> 290.59207 | E29: 0 | F29: =iferror(E29/$C$5,"") -> 0 | G29: 0 | H29: =iferror(G29/$C$5,"") -> 0
B30: Total Property Taxes | C30: 142164.14 | D30: =iferror(C30/$C$5,"") -> 772.6312 | E30: 0 | F30: =iferror(E30/$C$5,"") -> 0 | G30: 0 | H30: =iferror(G30/$C$5,"") -> 0
B31: Total Management Fees | C31: 104943.81 | D31: =iferror(C31/C18,"") -> 0.030750234 | E31: 0 | F31: =iferror(E31/$C$5,"") -> 0 | G31: 0 | H31: =iferror(G31/$C$5,"") -> 0
B32: Total Operating Expenses | C32: =sum(C21:C31) -> 1245455.1 | D32: =iferror(C32/$C$5,"") -> 6768.7777 | E32: =sum(E21:E31) -> 0 | F32: =iferror(E32/$C$5,"") -> 0 | G32: =sum(G21:G31) -> 0 | H32: =iferror(G32/$C$5,"") -> 0
B33: Expense Ratio | C33: =iferror(C32/C18,"") -> 0.36493849 | E33: =iferror(E32/E18,"") | G33: =iferror(G32/G18,"")
B35: Net Operating Income | C35: =C18-C32 -> 2167325.8 | D35: =iferror(C35/$C$5,"") -> 11778.944 | E35: =E18-E32 -> 0 | F35: =iferror(E35/$C$5,"") -> 0 | G35: =G18-G32 -> 0 | H35: =iferror(G35/$C$5,"") -> 0

Sheet Unit Mix & Comps
R2: Unit Mix | V2: Competitor Rate Analysis | AP2: Competitor Analysis
B3: ='Property Summary'!B3 -> Phoenix, AZ | R3: ='Property Summary'!I3 -> Wind River Group
B4: Rent Roll 2.10.25 | L4: Full Comps
H5: Current | I5: Gap in | J5: Average | L5: Market Average | O5: Market High | T5: Quick Look | Y5: =AP7 -> Allure at Tempe | AA5: =AP8 -> Carlyle at South Mtn | AC5: =AP9 -> Pointe at South Mtn | AE5: =AP10 -> Vista Sureno | AG5: =AP11 -> Strada Apartments | AI5: =AP12 -> Lore South Mtn | AK5: =AP13 -> Array South Mtn | AM5: =AP14 -> 505 West Apts. | AP5: Link property names to property websites
B6: Unit Mix | C6: Square Footage | D6: Units | E6: Occupied Units | F6: Renovation Units | G6: Unit Mix Percentage | H6: Advertised Rent | I6: Advertised to Achieved | J6: Achieved Rent | K6: Current Price Per SF | L6: Asking Rent | M6: Market Price Per SF | N6: Current - Market Price Per SF | O6: Asking Rent | P6: Renovated Rent | Q6: Renovated Rent Premium | R6: Premium % | T6: Market Rents | V6: Market Average SF | W6: Market Avg Rent | X6: Market Avg Price Per SF | Y6: =AQ7 -> 1.0 miles | Z6: Sqft | AA6: =AQ8 -> 1.5 | AB6: Sqft | AC6: =AQ9 -> 1.5 | AD6: Sqft | AE6: =AQ10 -> 1.3 | AF6: Sqft | AG6: =AQ11 -> 1.9 | AH6: Sqft | AI6: =AQ12 -> 1.4 | AJ6: Sqft | AK6: =AQ13 -> 1.5 | AL6: Sqft | AM6: =AQ14 -> 3.8 | AN6: Sqft | AP6: Property Name | AQ6: Distance | AR6: Year Built | AS6: Year Renovated | AT6: Units | AU6: Occupancy | AV6: Google Review Rating | AW6: Finish / Amenities / Condition
B7: 1 Bed- Classic | C7: 678 | D7: 16 | E7: 16 | F7: 10 | G7: =IFERROR(D7/$D$34,"") -> 0.086956522 | H7: 1245 | I7: =iferror((H7-J7)/H7,"") -> 0.11566265 | J7: 1101 | K7: =iferror(J7/$C7,"") -> 1.6238938 | L7: =ifs($L$4="Full Comps",W7,$L$4="Quick Look",T7) -> 1295 | M7: =iferror(if($L$4="Quick Look",L7/C7,X7),"") -> 1.9444444 | N7: =iferror(if(M7="","",(K7-M7)/K7),"") -> -0.19739631 | O7: 1357 | P7: =Q7+J7 -> 1325 | Q7: 224 | R7: =iferror(Q7/J7,"") -> 0.20345141 | T7: 1323 | V7: =iferror(AVERAGE(Z7,AB7,AD7,AF7,AH7,AJ7,AL7,AN7),"") -> 666 | W7: =iferror(average(Y7,AA7,AC7,AE7,AG7,AI7,AK7,AM7),"") -> 1295 | X7: =iferror(W7/V7,"") -> 1.9444444 | AG7: 1233 | AH7: 600 | AK7: 1357 | AL7: 732 | AP7: Allure at Tempe | AQ7: 1.0 miles | AR7: 1995 | AT7: 216 | AU7: 0.903 | AW7: Similar finish
B8: 1 Bed PU | C8: 678 | D8: 2 | E8: 1 | G8: =IFERROR(D8/$D$34,"") -> 0.010869565 | H8: 1430 | I8: =iferror((H8-J8)/H8,"") -> 0.083916084 | J8: 1310 | K8: =iferror(J8/$C8,"") -> 1.9321534 | L8: =ifs($L$4="Full Comps",W8,$L$4="Quick Look",T8) -> 1295 | M8: =iferror(if($L$4="Quick Look",L8/C8,X8),"") -> 1.9444444 | N8: =iferror(if(M8="","",(K8-M8)/K8),"") -> -0.0063613232 | P8: =Q8+J8 -> 1310 | R8: =iferror(Q8/J8,"") -> 0 | T8: 1323 | V8: =iferror(AVERAGE(Z8,AB8,AD8,AF8,AH8,AJ8,AL8,AN8),"") -> 666 | W8: =iferror(average(Y8,AA8,AC8,AE8,AG8,AI8,AK8,AM8),"") -> 1295 | X8: =iferror(W8/V8,"") -> 1.9444444 | AG8: 1233 | AH8: 600 | AK8: 1357 | AL8: 732 | AP8: Carlyle at South Mtn | AQ8: 1.5 | AR8: 1995 | AT8: 360 | AU8: 0.865
B9: 1 Bed U | C9: 678 | D9: 30 | E9: 29 | G9: =IFERROR(D9/$D$34,"") -> 0.16304348 | H9: 1422.76 | I9: =iferror((H9-J9)/H9,"") -> 0.1070806 | J9: 1270.41 | K9: =iferror(J9/$C9,"") -> 1.8737611 | L9: =ifs($L$4="Full Comps",W9,$L$4="Quick Look",T9) -> 1295 | M9: =iferror(if($L$4="Quick Look",L9/C9,X9),"") -> 1.9444444 | N9: =iferror(if(M9="","",(K9-M9)/K9),"") -> -0.03772273 | P9: =Q9+J9 -> 1270.41 | R9: =iferror(Q9/J9,"") -> 0 | T9: 1323 | V9: =iferror(AVERAGE(Z9,AB9,AD9,AF9,AH9,AJ9,AL9,AN9),"") -> 666 | W9: =iferror(average(Y9,AA9,AC9,AE9,AG9,AI9,AK9,AM9),"") -> 1295 | X9: =iferror(W9/V9,"") -> 1.9444444 | AG9: 1233 | AH9: 600 | AK9: 1357 | AL9: 732 | AP9: Pointe at South Mtn | AQ9: 1.5 | AR9: 1988 | AT9: 364 | AU9: 0.945
B10: 1 Bed Classic | C10: 734 | D10: 9 | E10: 9 | F10: 9 | G10: =IFERROR(D10/$D$34,"") -> 0.048913043 | H10: 1373.89 | I10: =iferror((H10-J10)/H10,"") -> 0.10150012 | J10: 1234.44 | K10: =iferror(J10/$C10,"") -> 1.6817984 | L10: =ifs($L$4="Full Comps",W10,$L$4="Quick Look",T10) -> 1305.2 | M10: =iferror(if($L$4="Quick Look",L10/C10,X10),"") -> 1.789416 | N10: =iferror(if(M10="","",(K10-M10)/K10),"") -> -0.063989593 | O10: 1389 | P10: =Q10+J10 -> 1385.44 | Q10: 151 | R10: =iferror(Q10/J10,"") -> 0.12232267 | T10: 1323 | V10: =iferror(AVERAGE(Z10,AB10,AD10,AF10,AH10,AJ10,AL10,AN10),"") -> 729.4 | W10: =iferror(average(Y10,AA10,AC10,AE10,AG10,AI10,AK10,AM10),"") -> 1305.2 | X10: =iferror(W10/V10,"") -> 1.789416 | AE10: 1328 | AF10: 740 | AG10: 1304 | AH10: 700 | AI10: 1319 | AJ10: 730 | AK10: 1389 | AL10: 757 | AM10: 1186 | AN10: 720 | AP10: Vista Sureno | AQ10: 1.3 | AR10: 1985 | AT10: 186 | AU10: 0.944
B11: 1 Bed PU | C11: 734 | D11: 1 | E11: 1 | G11: =IFERROR(D11/$D$34,"") -> 0.0054347826 | H11: 1480 | I11: =iferror((H11-J11)/H11,"") -> -0.23783784 | J11: 1832 | K11: =iferror(J11/$C11,"") -> 2.4959128 | L11: =ifs($L$4="Full Comps",W11,$L$4="Quick Look",T11) | M11: =iferror(if($L$4="Quick Look",L11/C11,X11),"") | N11: =iferror(if(M11="","",(K11-M11)/K11),"") | P11: =Q11+J11 -> 1832 | R11: =iferror(Q11/J11,"") -> 0 | T11: 1323 | V11: =iferror(AVERAGE(Z11,AB11,AD11,AF11,AH11,AJ11,AL11,AN11),"") | W11: =iferror(average(Y11,AA11,AC11,AE11,AG11,AI11,AK11,AM11),"") | X11: =iferror(W11/V11,"") | AP11: Strada Apartments | AQ11: 1.9 | AR11: 1987 | AT11: 495 | AU11: 0.945
B12: 1 Bed U | C12: 734 | D12: 14 | E12: 13 | G12: =IFERROR(D12/$D$34,"") -> 0.076086957 | H12: 1488.46 | I12: =iferror((H12-J12)/H12,"") -> 0.074781989 | J12: 1377.15 | K12: =iferror(J12/$C12,"") -> 1.8762262 | L12: =ifs($L$4="Full Comps",W12,$L$4="Quick Look",T12) | M12: =iferror(if($L$4="Quick Look",L12/C12,X12),"") | N12: =iferror(if(M12="","",(K12-M12)/K12),"") | P12: =Q12+J12 -> 1377.15 | R12: =iferror(Q12/J12,"") -> 0 | T12: 1323 | V12: =iferror(AVERAGE(Z12,AB12,AD12,AF12,AH12,AJ12,AL12,AN12),"") | W12: =iferror(average(Y12,AA12,AC12,AE12,AG12,AI12,AK12,AM12),"") | X12: =iferror(W12/V12,"") | AP12: Lore South Mtn | AQ12: 1.4 | AR12: 1987 | AT12: 242 | AU12: 0.905
B13: 1 Bed C | C13: 771 | D13: 13 | E13: 12 | F13: 10 | G13: =IFERROR(D13/$D$34,"") -> 0.070652174 | H13: 1377.92 | I13: =iferror((H13-J13)/H13,"") -> 0.079590978 | J13: 1268.25 | K13: =iferror(J13/$C13,"") -> 1.6449416 | L13: =ifs($L$4="Full Comps",W13,$L$4="Quick Look",T13) -> 1357.3333 | M13: =iferror(if($L$4="Quick Look",L13/C13,X13),"") -> 1.7239627 | N13: =iferror(if(M13="","",(K13-M13)/K13),"") -> -0.048038853 | P13: =Q13+J13 -> 1400.25 | Q13: 132 | R13: =iferror(Q13/J13,"") -> 0.10408043 | T13: 1323 | V13: =iferror(AVERAGE(Z13,AB13,AD13,AF13,AH13,AJ13,AL13,AN13),"") -> 787.33333 | W13: =iferror(average(Y13,AA13,AC13,AE13,AG13,AI13,AK13,AM13),"") -> 1357.3333 | X13: =iferror(W13/V13,"") -> 1.7239627 | AA13: 1403 | AB13: 786 | AC13: 1347 | AD13: 751 | AG13: 1322 | AH13: 825 | AP13: Array South Mtn | AQ13: 1.5 | AR13: 1991 | AT13: 600 | AU13: 0.897
B14: 1 Bed PU | C14: 771 | D14: 1 | E14: 1 | G14: =IFERROR(D14/$D$34,"") -> 0.0054347826 | H14: 1485 | I14: =iferror((H14-J14)/H14,"") -> 0.05993266 | J14: 1396 | K14: =iferror(J14/$C14,"") -> 1.8106355 | L14: =ifs($L$4="Full Comps",W14,$L$4="Quick Look",T14) | M14: =iferror(if($L$4="Quick Look",L14/C14,X14),"") | N14: =iferror(if(M14="","",(K14-M14)/K14),"") | P14: =Q14+J14 -> 1396 | R14: =iferror(Q14/J14,"") -> 0 | T14: 1323 | V14: =iferror(AVERAGE(Z14,AB14,AD14,AF14,AH14,AJ14,AL14,AN14),"") | W14: =iferror(average(Y14,AA14,AC14,AE14,AG14,AI14,AK14,AM14),"") | X14: =iferror(W14/V14,"") | AP14: 505 West Apts. | AQ14: 3.8 | AR14: 1981 | AT14: 334 | AU14: 0.955
B15: 1 Bed U | C15: 771 | D15: 9 | E15: 9 | G15: =IFERROR(D15/$D$34,"") -> 0.048913043 | H15: 1513.33 | I15: =iferror((H15-J15)/H15,"") -> 0.083550845 | J15: 1386.89 | K15: =iferror(J15/$C15,"") -> 1.7988197 | L15: =ifs($L$4="Full Comps",W15,$L$4="Quick Look",T15) | M15: =iferror(if($L$4="Quick Look",L15/C15,X15),"") | N15: =iferror(if(M15="","",(K15-M15)/K15),"") | P15: =Q15+J15 -> 1386.89 | R15: =iferror(Q15/J15,"") -> 0 | T15: 1323 | V15: =iferror(AVERAGE(Z15,AB15,AD15,AF15,AH15,AJ15,AL15,AN15),"") | W15: =iferror(average(Y15,AA15,AC15,AE15,AG15,AI15,AK15,AM15),"") | X15: =iferror(W15/V15,"") | AP15: Average | AQ15: =iferror(average(AQ7:AQ14),"") -> 1.8428571 | AR15: =iferror(average(AR7:AR14),"") -> 1988.625 | AS15: =iferror(average(AS7:AS14),"") | AT15: =iferror(average(AT7:AT14),"") -> 349.625 | AU15: =iferror(average(AU7:AU14),"") -> 0.919875 | AV15: =iferror(average(AV7:AV14),"")
B16: 2B / 1B -C | C16: 863 | D16: 9 | E16: 9 | F16: 10 | G16: =IFERROR(D16/$D$34,"") -> 0.048913043 | H16: 1514 | I16: =iferror((H16-J16)/H16,"") -> 0.18949141 | J16: 1227.11 | K16: =iferror(J16/$C16,"") -> 1.4219119 | L16: =ifs($L$4="Full Comps",W16,$L$4="Quick Look",T16) -> 1417 | M16: =iferror(if($L$4="Quick Look",L16/C16,X16),"") -> 1.6749409 | N16: =iferror(if(M16="","",(K16-M16)/K16),"") -> -0.17794981 | O16: 1417 | P16: =Q16+J16 -> 1475.11 | Q16: 248 | R16: =iferror(Q16/J16,"") -> 0.20210087 | T16: 1553 | V16: =iferror(AVERAGE(Z16,AB16,AD16,AF16,AH16,AJ16,AL16,AN16),"") -> 846 | W16: =iferror(average(Y16,AA16,AC16,AE16,AG16,AI16,AK16,AM16),"") -> 1417 | X16: =iferror(W16/V16,"") -> 1.6749409 | AM16: 1417 | AN16: 846
B17: 2B / 1B -E | C17: 863 | D17: 1 | E17: 1 | G17: =IFERROR(D17/$D$34,"") -> 0.0054347826 | H17: 1654 | I17: =iferror((H17-J17)/H17,"") -> 0.066505441 | J17: 1544 | K17: =iferror(J17/$C17,"") -> 1.7891078 | L17: =ifs($L$4="Full Comps",W17,$L$4="Quick Look",T17) | M17: =iferror(if($L$4="Quick Look",L17/C17,X17),"") | N17: =iferror(if(M17="","",(K17-M17)/K17),"") | P17: =Q17+J17 -> 1544 | R17: =iferror(Q17/J17,"") -> 0 | T17: 1553 | V17: =iferror(AVERAGE(Z17,AB17,AD17,AF17,AH17,AJ17,AL17,AN17),"") | W17: =iferror(average(Y17,AA17,AC17,AE17,AG17,AI17,AK17,AM17),"") | X17: =iferror(W17/V17,"")
B18: 2B / 1B -U | C18: 863 | D18: 14 | E18: 13 | G18: =IFERROR(D18/$D$34,"") -> 0.076086957 | H18: 1629 | I18: =iferror((H18-J18)/H18,"") -> 0.09704113 | J18: 1470.92 | K18: =iferror(J18/$C18,"") -> 1.7044264 | L18: =ifs($L$4="Full Comps",W18,$L$4="Quick Look",T18) | M18: =iferror(if($L$4="Quick Look",L18/C18,X18),"") | N18: =iferror(if(M18="","",(K18-M18)/K18),"") | P18: =Q18+J18 -> 1470.92 | R18: =iferror(Q18/J18,"") -> 0 | T18: 1553 | V18: =iferror(AVERAGE(Z18,AB18,AD18,AF18,AH18,AJ18,AL18,AN18),"") | W18: =iferror(average(Y18,AA18,AC18,AE18,AG18,AI18,AK18,AM18),"") | X18: =iferror(W18/V18,"")
B19: 2B/ 2B- C | C19: 958 | D19: 4 | E19: 4 | G19: =IFERROR(D19/$D$34,"") -> 0.02173913 | H19: 1611.75 | I19: =iferror((H19-J19)/H19,"") -> 0.026058632 | J19: 1569.75 | K19: =iferror(J19/$C19,"") -> 1.6385699 | L19: =ifs($L$4="Full Comps",W19,$L$4="Quick Look",T19) -> 1535.8571 | M19: =iferror(if($L$4="Quick Look",L19/C19,X19),"") -> 1.5683443 | N19: =iferror(if(M19="","",(K19-M19)/K19),"") -> 0.042857898 | O19: 1650 | P19: =Q19+J19 -> 1569.75 | R19: =iferror(Q19/J19,"") -> 0 | T19: 1553 | V19: =iferror(AVERAGE(Z19,AB19,AD19,AF19,AH19,AJ19,AL19,AN19),"") -> 979.28571 | W19: =iferror(average(Y19,AA19,AC19,AE19,AG19,AI19,AK19,AM19),"") -> 1535.8571 | X19: =iferror(W19/V19,"") -> 1.5683443 | Y19: 1554 | Z19: 948 | AC19: 1613 | AD19: 983 | AE19: 1556 | AF19: 924 | AG19: 1546 | AH19: 1010 | AI19: 1398 | AJ19: 960 | AK19: 1582 | AL19: 1024 | AM19: 1502 | AN19: 1006
B20: 2B/ 2B- PU | C20: 958 | D20: 3 | E20: 3 | G20: =IFERROR(D20/$D$34,"") -> 0.016304348 | H20: 1764.67 | I20: =iferror((H20-J20)/H20,"") -> 0.2079709 | J20: 1397.67 | K20: =iferror(J20/$C20,"") -> 1.4589457 | L20: =ifs($L$4="Full Comps",W20,$L$4="Quick Look",T20) | M20: =iferror(if($L$4="Quick Look",L20/C20,X20),"") | N20: =iferror(if(M20="","",(K20-M20)/K20),"") | P20: =Q20+J20 -> 1397.67 | R20: =iferror(Q20/J20,"") -> 0 | T20: 1553 | V20: =iferror(AVERAGE(Z20,AB20,AD20,AF20,AH20,AJ20,AL20,AN20),"") | W20: =iferror(average(Y20,AA20,AC20,AE20,AG20,AI20,AK20,AM20),"") | X20: =iferror(W20/V20,"")
B21: 2B/ 2B- U | C21: 958 | D21: 9 | E21: 6 | G21: =IFERROR(D21/$D$34,"") -> 0.048913043 | H21: 1753.56 | I21: =iferror((H21-J21)/H21,"") -> 0.097932206 | J21: 1581.83 | K21: =iferror(J21/$C21,"") -> 1.6511795 | L21: =ifs($L$4="Full Comps",W21,$L$4="Quick Look",T21) | M21: =iferror(if($L$4="Quick Look",L21/C21,X21),"") | N21: =iferror(if(M21="","",(K21-M21)/K21),"") | P21: =Q21+J21 -> 1581.83 | R21: =iferror(Q21/J21,"") -> 0 | T21: 1553 | V21: =iferror(AVERAGE(Z21,AB21,AD21,AF21,AH21,AJ21,AL21,AN21),"") | W21: =iferror(average(Y21,AA21,AC21,AE21,AG21,AI21,AK21,AM21),"") | X21: =iferror(W21/V21,"")
B22: 2B/2B C | C22: 1000 | D22: 7 | E22: 7 | F22: 7 | G22: =IFERROR(D22/$D$34,"") -> 0.038043478 | H22: 1679.29 | I22: =iferror((H22-J22)/H22,"") -> 0.15432117 | J22: 1420.14 | K22: =iferror(J22/$C22,"") -> 1.42014 | L22: =ifs($L$4="Full Comps",W22,$L$4="Quick Look",T22) -> 1630.6667 | M22: =iferror(if($L$4="Quick Look",L22/C22,X22),"") -> 1.5345044 | N22: =iferror(if(M22="","",(K22-M22)/K22),"") -> -0.080530364 | O22: 1671 | P22: =Q22+J22 -> 1650.14 | Q22: 230 | R22: =iferror(Q22/J22,"") -> 0.16195586 | T22: 1553 | V22: =iferror(AVERAGE(Z22,AB22,AD22,AF22,AH22,AJ22,AL22,AN22),"") -> 1062.6667 | W22: =iferror(average(Y22,AA22,AC22,AE22,AG22,AI22,AK22,AM22),"") -> 1630.6667 | X22: =iferror(W22/V22,"") -> 1.5345044 | AA22: 1630 | AB22: 1068 | AG22: 1671 | AH22: 1076 | AK22: 1591 | AL22: 1044
B23: 2B/ 2B- PU | C23: 1000 | D23: 3 | E23: 3 | G23: =IFERROR(D23/$D$34,"") -> 0.016304348 | H23: 1788.33 | I23: =iferror((H23-J23)/H23,"") -> 0.11761252 | J23: 1578 | K23: =iferror(J23/$C23,"") -> 1.578 | L23: =ifs($L$4="Full Comps",W23,$L$4="Quick Look",T23) | M23: =iferror(if($L$4="Quick Look",L23/C23,X23),"") | N23: =iferror(if(M23="","",(K23-M23)/K23),"") | P23: =Q23+J23 -> 1578 | R23: =iferror(Q23/J23,"") -> 0 | T23: 1553 | V23: =iferror(AVERAGE(Z23,AB23,AD23,AF23,AH23,AJ23,AL23,AN23),"") | W23: =iferror(average(Y23,AA23,AC23,AE23,AG23,AI23,AK23,AM23),"") | X23: =iferror(W23/V23,"")
B24: 2B/ 2B- U | C24: 1000 | D24: 22 | E24: 18 | G24: =IFERROR(D24/$D$34,"") -> 0.11956522 | H24: 1803.18 | I24: =iferror((H24-J24)/H24,"") -> 0.10608481 | J24: 1611.89 | K24: =iferror(J24/$C24,"") -> 1.61189 | L24: =ifs($L$4="Full Comps",W24,$L$4="Quick Look",T24) | M24: =iferror(if($L$4="Quick Look",L24/C24,X24),"") | N24: =iferror(if(M24="","",(K24-M24)/K24),"") | P24: =Q24+J24 -> 1611.89 | R24: =iferror(Q24/J24,"") -> 0 | T24: 1553 | V24: =iferror(AVERAGE(Z24,AB24,AD24,AF24,AH24,AJ24,AL24,AN24),"") | W24: =iferror(average(Y24,AA24,AC24,AE24,AG24,AI24,AK24,AM24),"") | X24: =iferror(W24/V24,"")
B25: 2B/2B C | C25: 1040 | D25: 3 | E25: 3 | F25: 3 | G25: =IFERROR(D25/$D$34,"") -> 0.016304348 | H25: 1696 | I25: =iferror((H25-J25)/H25,"") -> 0.14091981 | J25: 1457 | K25: =iferror(J25/$C25,"") -> 1.4009615 | L25: =ifs($L$4="Full Comps",W25,$L$4="Quick Look",T25) | M25: =iferror(if($L$4="Quick Look",L25/C25,X25),"") | N25: =iferror(if(M25="","",(K25-M25)/K25),"") | P25: =Q25+J25 -> 1655 | Q25: 198 | R25: =iferror(Q25/J25,"") -> 0.13589568 | T25: 1553 | V25: =iferror(AVERAGE(Z25,AB25,AD25,AF25,AH25,AJ25,AL25,AN25),"") | W25: =iferror(average(Y25,AA25,AC25,AE25,AG25,AI25,AK25,AM25),"") | X25: =iferror(W25/V25,"")
B26: 2B/ 2B- PU | C26: 1040 | D26: 1 | E26: 1 | G26: =IFERROR(D26/$D$34,"") -> 0.0054347826 | H26: 1829 | I26: =iferror((H26-J26)/H26,"") -> 0.13395298 | J26: 1584 | K26: =iferror(J26/$C26,"") -> 1.5230769 | L26: =ifs($L$4="Full Comps",W26,$L$4="Quick Look",T26) | M26: =iferror(if($L$4="Quick Look",L26/C26,X26),"") | N26: =iferror(if(M26="","",(K26-M26)/K26),"") | P26: =Q26+J26 -> 1584 | R26: =iferror(Q26/J26,"") -> 0 | T26: 1553 | V26: =iferror(AVERAGE(Z26,AB26,AD26,AF26,AH26,AJ26,AL26,AN26),"") | W26: =iferror(average(Y26,AA26,AC26,AE26,AG26,AI26,AK26,AM26),"") | X26: =iferror(W26/V26,"")
B27: 2B/ 2B- U | C27: 1040 | D27: 13 | E27: 10 | G27: =IFERROR(D27/$D$34,"") -> 0.070652174 | H27: 1825.15 | I27: =iferror((H27-J27)/H27,"") -> 0.10555297 | J27: 1632.5 | K27: =iferror(J27/$C27,"") -> 1.5697115 | L27: =ifs($L$4="Full Comps",W27,$L$4="Quick Look",T27) | M27: =iferror(if($L$4="Quick Look",L27/C27,X27),"") | N27: =iferror(if(M27="","",(K27-M27)/K27),"") | P27: =Q27+J27 -> 1632.5 | R27: =iferror(Q27/J27,"") -> 0 | T27: 1553 | V27: =iferror(AVERAGE(Z27,AB27,AD27,AF27,AH27,AJ27,AL27,AN27),"") | W27: =iferror(average(Y27,AA27,AC27,AE27,AG27,AI27,AK27,AM27),"") | X27: =iferror(W27/V27,"")
G28: =IFERROR(D28/$D$34,"") -> 0 | I28: =iferror((H28-J28)/H28,"") | K28: =iferror(J28/$C28,"") | L28: =ifs($L$4="Full Comps",W28,$L$4="Quick Look",T28) | M28: =iferror(if($L$4="Quick Look",L28/C28,X28),"") | N28: =iferror(if(M28="","",(K28-M28)/K28),"") | P28: =Q28+J28 -> 0 | R28: =iferror(Q28/J28,"") | V28: =iferror(AVERAGE(Z28,AB28,AD28,AF28,AH28,AJ28,AL28,AN28),"") | W28: =iferror(average(Y28,AA28,AC28,AE28,AG28,AI28,AK28,AM28),"") | X28: =iferror(W28/V28,"")
G29: =IFERROR(D29/$D$34,"") -> 0 | I29: =iferror((H29-J29)/H29,"") | K29: =iferror(J29/$C29,"") | L29: =ifs($L$4="Full Comps",W29,$L$4="Quick Look",T29) | M29: =iferror(if($L$4="Quick Look",L29/C29,X29),"") | N29: =iferror(if(M29="","",(K29-M29)/K29),"") | P29: =Q29+J29 -> 0 | R29: =iferror(Q29/J29,"") | V29: =iferror(AVERAGE(Z29,AB29,AD29,AF29,AH29,AJ29,AL29,AN29),"") | W29: =iferror(average(Y29,AA29,AC29,AE29,AG29,AI29,AK29,AM29),"") | X29: =iferror(W29/V29,"")
G30: =IFERROR(D30/$D$34,"") -> 0 | I30: =iferror((H30-J30)/H30,"") | K30: =iferror(J30/$C30,"") | L30: =ifs($L$4="Full Comps",W30,$L$4="Quick Look",T30) | M30: =iferror(if($L$4="Quick Look",L30/C30,X30),"") | N30: =iferror(if(M30="","",(K30-M30)/K30),"") | P30: =Q30+J30 -> 0 | R30: =iferror(Q30/J30,"") | V30: =iferror(AVERAGE(Z30,AB30,AD30,AF30,AH30,AJ30,AL30,AN30),"") | W30: =iferror(average(Y30,AA30,AC30,AE30,AG30,AI30,AK30,AM30),"") | X30: =iferror(W30/V30,"")
G31: =IFERROR(D31/$D$34,"") -> 0 | I31: =iferror((H31-J31)/H31,"") | K31: =iferror(J31/$C31,"") | L31: =ifs($L$4="Full Comps",W31,$L$4="Quick Look",T31) | M31: =iferror(if($L$4="Quick Look",L31/C31,X31),"") | N31: =iferror(if(M31="","",(K31-M31)/K31),"") | P31: =Q31+J31 -> 0 | R31: =iferror(Q31/J31,"") | V31: =iferror(AVERAGE(Z31,AB31,AD31,AF31,AH31,AJ31,AL31,AN31),"") | W31: =iferror(average(Y31,AA31,AC31,AE31,AG31,AI31,AK31,AM31),"") | X31: =iferror(W31/V31,"")
G32: =IFERROR(D32/$D$34,"") -> 0 | I32: =iferror((H32-J32)/H32,"") | K32: =iferror(J32/$C32,"") | L32: =ifs($L$4="Full Comps",W32,$L$4="Quick Look",T32) | M32: =iferror(if($L$4="Quick Look",L32/C32,X32),"") | N32: =iferror(if(M32="","",(K32-M32)/K32),"") | P32: =Q32+J32 -> 0 | R32: =iferror(Q32/J32,"") | V32: =iferror(AVERAGE(Z32,AB32,AD32,AF32,AH32,AJ32,AL32,AN32),"") | W32: =iferror(average(Y32,AA32,AC32,AE32,AG32,AI32,AK32,AM32),"") | X32: =iferror(W32/V32,"")
G33: =IFERROR(D33/$D$34,"") -> 0 | I33: =iferror((H33-J33)/H33,"") | K33: =iferror(J33/$C33,"") | L33: =ifs($L$4="Full Comps",W33,$L$4="Quick Look",T33) | M33: =iferror(if($L$4="Quick Look",L33/C33,X33),"") | N33: =iferror(if(M33="","",(K33-M33)/K33),"") | P33: =Q33+J33 -> 0 | R33: =iferror(Q33/J33,"") | V33: =iferror(AVERAGE(Z33,AB33,AD33,AF33,AH33,AJ33,AL33,AN33),"") | W33: =iferror(average(Y33,AA33,AC33,AE33,AG33,AI33,AK33,AM33),"") | X33: =iferror(W33/V33,"")
B34: Total | C34: =iferror(SUMPRODUCT(C7:C33,D7:D33),"") -> 153613 | D34: =IFERROR(SUM(D7:D33),"") -> 184 | E34: =IFERROR(SUM(E7:E33),"") -> 169 | F34: =IFERROR(SUM(F7:F33),"") -> 49 | G34: =IFERROR(D34/$D$34,"") -> 1 | J34: =iferror(sumproduct(D7:D33,J7:J33),"") -> 256139.03 | W34: Average Price Per SF | X34: =iferror(average(X7:X33),"") -> 1.7655627
B35: Avg SF Per Unit | C35: =iferror(C34/D34,"") -> 834.85326 | D35: Current Occupancy | E35: =iferror(E34/D34,"") -> 0.91847826 | F35: =F34/D34 -> 0.26630435 | G35: Avg | I35: =iferror(average(I7:I33),"") -> 0.091029622 | J35: =iferror(J34/$D$34,"") -> 1392.0599 | N35: =iferror(average(N7:N33),"") -> -0.071141386 | Q35: =iferror(sumproduct(Q7:Q33,F7:F33)/F34,"") -> 195.97959
B38: Classic (no letter)
B39: Prior Upgrade- pu
B40: Upgrade- u
B41: Elite-e
B42: Prior Upgrade (PU) - stainless or black appliances, dark grey cabinets, some with hardware, formica, no backsplash, new carpet & vinyl – 10 units
B45: Upgrade(u) - backsplash, stainless steel appliances, hardware on cabinets, white cabinets, resurfaced counter tops, new vinyl & carpet, full paint – 111 units
...

Sheet Revenue
M2: Property Revenue
B3: ='Property Summary'!B3 -> Phoenix, AZ | M3: ='Property Summary'!I3 -> Wind River Group
B5: Anticipated RUBS Income | H5: Unit Renovations
B6: Water/Sewer | C6: 92 | D6: RUBS Collection % | E6: 1 | H6: Renovation Start Month | I6: 4
B7: Trash | C7: 0 | H7: Units Per Month | I7: 3
B8: Pest Control | C8: 0 | H8: Total Renovation Units | I8: ='Unit Mix & Comps'!F34 -> 49
B9: Package Hub | C9: 0 | H9: Unit Type / SF | I9: Renovation Units | J9: Current Rent | K9: Rent Premium
B10: Valet Trash | C10: 0 | H10: ='Unit Mix & Comps'!B7&", "&'Unit Mix & Comps'!C7&" SF" -> 1 Bed- Classic, 678 SF | I10: ='Unit Mix & Comps'!F7 -> 10 | J10: ='Unit Mix & Comps'!J7 -> 1101 | K10: ='Unit Mix & Comps'!Q7 -> 224
B11: Year 1 RUBS Per Unit | C11: =sum(C6:C10) -> 92 | H11: ='Unit Mix & Comps'!B10&", "&'Unit Mix & Comps'!C10&" SF" -> 1 Bed Classic, 734 SF | I11: ='Unit Mix & Comps'!F10 -> 9 | J11: ='Unit Mix & Comps'!J10 -> 1234.44 | K11: ='Unit Mix & Comps'!Q10 -> 151
H12: ='Unit Mix & Comps'!B13&", "&'Unit Mix & Comps'!C13&" SF" -> 1 Bed C, 771 SF | I12: ='Unit Mix & Comps'!F13 -> 10 | J12: ='Unit Mix & Comps'!J13 -> 1268.25 | K12: ='Unit Mix & Comps'!Q13 -> 132
B13: Anticipated Other Income | C13: T-12 | D13: Unit / Month | E13: Year 1 Proforma | F13: Proforma / Unit | H13: ='Unit Mix & Comps'!B16&", "&'Unit Mix & Comps'!C16&" SF" -> 2B / 1B -C, 863 SF | I13: ='Unit Mix & Comps'!F16 -> 10 | J13: ='Unit Mix & Comps'!J16 -> 1227.11 | K13: ='Unit Mix & Comps'!Q16 -> 248
B14: Total Other Income (-RUBS) | C14: 401185 | D14: =iferror(C14/'Unit Mix & Comps'!$D$34/12,"") -> 181.69611 | E14: 405000 | F14: =iferror(E14/'Unit Mix & Comps'!$D$34/12,"") -> 183.42391 | H14: ='Unit Mix & Comps'!B19&", "&'Unit Mix & Comps'!C19&" SF" -> 2B/ 2B- C, 958 SF | I14: ='Unit Mix & Comps'!F19 | J14: ='Unit Mix & Comps'!J19 -> 1569.75 | K14: ='Unit Mix & Comps'!Q19
H15: ='Unit Mix & Comps'!B22&", "&'Unit Mix & Comps'!C22&" SF" -> 2B/2B C, 1000 SF | I15: ='Unit Mix & Comps'!F22 -> 7 | J15: ='Unit Mix & Comps'!J22 -> 1420.14 | K15: ='Unit Mix & Comps'!Q22 -> 230
B16: Gross Potential Rents | C16: Monthly | D16: Annual | E16: Avg Price Per Unit | F16: Above/Below Market | H16: ='Unit Mix & Comps'!B25&", "&'Unit Mix & Comps'!C25&" SF" -> 2B/2B C, 1040 SF | I16: ='Unit Mix & Comps'!F25 -> 3 | J16: ='Unit Mix & Comps'!J25 -> 1457 | K16: ='Unit Mix & Comps'!Q25 -> 198
B17: Current Rent | C17: =iferror('Unit Mix & Comps'!J34,"") -> 256139.03 | D17: =C17*12 -> 3073668.4 | E17: ='Unit Mix & Comps'!J35 -> 1392.0599 | F17: ='Unit Mix & Comps'!N35 -> -0.071141386 | H17: ='Unit Mix & Comps'!B26&", "&'Unit Mix & Comps'!C26&" SF" -> 2B/ 2B- PU, 1040 SF | I17: ='Unit Mix & Comps'!F26 | J17: ='Unit Mix & Comps'!J26 -> 1584 | K17: ='Unit Mix & Comps'!Q26
B18: Market Rent | C18: =E18*'Unit Mix & Comps'!D34 -> 274361.12 | D18: =C18*12 -> 3292333.4 | E18: =iferror(E17*(1-F17),"") -> 1491.093 | H18: ='Unit Mix & Comps'!B27&", "&'Unit Mix & Comps'!C27&" SF" -> 2B/ 2B- U, 1040 SF | I18: ='Unit Mix & Comps'!F27 | J18: ='Unit Mix & Comps'!J27 -> 1632.5 | K18: ='Unit Mix & Comps'!Q27
B19: Renovated Rent Premium | C19: =iferror(sumproduct('Unit Mix & Comps'!F7:F33,'Unit Mix & Comps'!Q7:Q33),"") -> 9603 | D19: =C19*12 -> 115236 | E19: ='Unit Mix & Comps'!Q35 -> 195.97959 | H19: ='Unit Mix & Comps'!B28&", "&'Unit Mix & Comps'!C28&" SF" -> , SF | I19: ='Unit Mix & Comps'!F28 | J19: ='Unit Mix & Comps'!J28 | K19: ='Unit Mix & Comps'!Q28
B20: Avg Market Rent Growth | C20: 0.035 | H20: ='Unit Mix & Comps'!B29&", "&'Unit Mix & Comps'!C29&" SF" -> , SF | I20: ='Unit Mix & Comps'!F29 | J20: ='Unit Mix & Comps'!J29 | K20: ='Unit Mix & Comps'!Q29
H21: ='Unit Mix & Comps'!B30&", "&'Unit Mix & Comps'!C30&" SF" -> , SF | I21: ='Unit Mix & Comps'!F30 | J21: ='Unit Mix & Comps'!J30 | K21: ='Unit Mix & Comps'!Q30
H22: ='Unit Mix & Comps'!B31&", "&'Unit Mix & Comps'!C31&" SF" -> , SF | I22: ='Unit Mix & Comps'!F31 | J22: ='Unit Mix & Comps'!J31 | K22: ='Unit Mix & Comps'!Q31
H23: ='Unit Mix & Comps'!B32&", "&'Unit Mix & Comps'!C32&" SF" -> , SF | I23: ='Unit Mix & Comps'!F32 | J23: ='Unit Mix & Comps'!J32 | K23: ='Unit Mix & Comps'!Q32
H24: ='Unit Mix & Comps'!B33&", "&'Unit Mix & Comps'!C33&" SF" -> , SF | I24: ='Unit Mix & Comps'!F33 | J24: ='Unit Mix & Comps'!J33 | K24: ='Unit Mix & Comps'!Q33
B26: Income Growth Assumptions | C26: 1 | D26: 2 | E26: 3 | F26: 4 | G26: 5 | H26: 6 | I26: 7 | J26: 8 | K26: 9 | L26: 10
B27: RUBS Income Growth | C27: 0 | D27: 0.02 | E27: =$D$27 -> 0.02 | F27: =$D$27 -> 0.02 | G27: =$D$27 -> 0.02 | H27: =$D$27 -> 0.02 | I27: =$D$27 -> 0.02 | J27: =$D$27 -> 0.02 | K27: =$D$27 -> 0.02 | L27: =$D$27 -> 0.02
B28: Monthly RUBS Income Per Unit | C28: =iferror(C11*(1+C27),"") -> 92 | D28: =iferror(C28*(1+D$27),"") -> 93.84 | E28: =iferror(D28*(1+E$27),"") -> 95.7168 | F28: =iferror(E28*(1+F$27),"") -> 97.631136 | G28: =iferror(F28*(1+G$27),"") -> 99.583759 | H28: =iferror(G28*(1+H$27),"") -> 101.57543 | I28: =iferror(H28*(1+I$27),"") -> 103.60694 | J28: =iferror(I28*(1+J$27),"") -> 105.67908 | K28: =iferror(J28*(1+K$27),"") -> 107.79266 | L28: =iferror(K28*(1+L$27),"") -> 109.94852
B29: Other Income Growth | C29: 0 | D29: 0.02 | E29: =$D$29 -> 0.02 | F29: =$D$29 -> 0.02 | G29: =$D$29 -> 0.02 | H29: =$D$29 -> 0.02 | I29: =$D$29 -> 0.02 | J29: =$D$29 -> 0.02 | K29: =$D$29 -> 0.02 | L29: =$D$29 -> 0.02
B30: Rental Income Growth | C30: 0.035 | D30: 0.035 | E30: 0.035 | F30: 0.035 | G30: =$C$20 -> 0.035 | H30: =$C$20 -> 0.035 | I30: =$C$20 -> 0.035 | J30: =$C$20 -> 0.035 | K30: =$C$20 -> 0.035 | L30: =$C$20 -> 0.035
B31: Avg Current Rent | C31: =iferror(E17*(1+C30),"") -> 1440.782 | D31: =iferror(C31*(1+D$30),"") -> 1491.2094 | E31: =iferror(D31*(1+E$30),"") -> 1543.4017 | F31: =iferror(E31*(1+F$30),"") -> 1597.4208 | G31: =iferror(F31*(1+G$30),"") -> 1653.3305 | H31: =iferror(G31*(1+H$30),"") -> 1711.1971 | I31: =iferror(H31*(1+I$30),"") -> 1771.089 | J31: =iferror(I31*(1+J$30),"") -> 1833.0771 | K31: =iferror(J31*(1+K$30),"") -> 1897.2348 | L31: =iferror(K31*(1+L$30),"") -> 1963.638
B32: Avg Monthly Market Rent | C32: =iferror(E18*(1+C20),"") -> 1543.2813 | D32: =iferror(C32*(1+$C$20),"") -> 1597.2961 | E32: =iferror(D32*(1+$C$20),"") -> 1653.2015 | F32: =iferror(E32*(1+$C$20),"") -> 1711.0635 | G32: =iferror(F32*(1+$C$20),"") -> 1770.9508 | H32: =iferror(G32*(1+$C$20),"") -> 1832.934 | I32: =iferror(H32*(1+$C$20),"") -> 1897.0867 | J32: =iferror(I32*(1+$C$20),"") -> 1963.4848 | K32: =iferror(J32*(1+$C$20),"") -> 2032.2067 | L32: =iferror(K32*(1+$C$20),"") -> 2103.334
B33: Avg Monthly Renovated Rent | C33: =iferror(sum(E17,E19),"") -> 1588.0395 | D33: =iferror(C33*(1+$C$20),"") -> 1643.6209 | E33: =iferror(D33*(1+$C$20),"") -> 1701.1477 | F33: =iferror(E33*(1+$C$20),"") -> 1760.6878 | G33: =iferror(F33*(1+$C$20),"") -> 1822.3119 | H33: =iferror(G33*(1+$C$20),"") -> 1886.0928 | I33: =iferror(H33*(1+$C$20),"") -> 1952.1061 | J33: =iferror(I33*(1+$C$20),"") -> 2020.4298 | K33: =iferror(J33*(1+$C$20),"") -> 2091.1448 | L33: =iferror(K33*(1+$C$20),"") -> 2164.3349
B34: Vacancy Loss | C34: 0.08 | D34: 0.08 | E34: 0.07 | F34: 0.07 | G34: =$F$34 -> 0.07 | H34: =$F$34 -> 0.07 | I34: =$F$34 -> 0.07 | J34: =$F$34 -> 0.07 | K34: =$F$34 -> 0.07 | L34: =$F$34 -> 0.07
B35: Bad Debt Expense | C35: 0.015 | D35: 0.0125 | E35: =$D$35 -> 0.0125 | F35: =$E$35 -> 0.0125 | G35: =$E$35 -> 0.0125 | H35: =$E$35 -> 0.0125 | I35: =$E$35 -> 0.0125 | J35: =$E$35 -> 0.0125 | K35: =$E$35 -> 0.0125 | L35: =$E$35 -> 0.0125
B36: Concessions | C36: 0.0125 | D36: =$C$36 -> 0.0125 | E36: =$C$36 -> 0.0125 | F36: =$C$36 -> 0.0125 | G36: =$C$36 -> 0.0125 | H36: =$C$36 -> 0.0125 | I36: =$C$36 -> 0.0125 | J36: =$C$36 -> 0.0125 | K36: =$C$36 -> 0.0125 | L36: =$C$36 -> 0.0125
B38: Projected Annual Revenue
C41: T-12 | D41: 1 | E41: 2 | F41: 3 | G41: 4 | H41: 5 | I41: 6 | J41: 7 | K41: 8 | L41: 9 | M41: 10
B42: Year End Total Units | C42: ='Historical Financials'!C5 -> 184 | D42: =iferror(lookup(D$41*12,$D$61:$DS$61,$D$63:$DS$63),"") -> 184 | E42: =iferror(lookup(E$41*12,$D$61:$DS$61,$D$63:$DS$63),"") -> 184 | F42: =iferror(lookup(F$41*12,$D$61:$DS$61,$D$63:$DS$63),"") -> 184 | G42: =iferror(lookup(G$41*12,$D$61:$DS$61,$D$63:$DS$63),"") -> 184 | H42: =iferror(lookup(H$41*12,$D$61:$DS$61,$D$63:$DS$63),"") -> 184 | I42: =iferror(lookup(I$41*12,$D$61:$DS$61,$D$63:$DS$63),"") -> 184 | J42: =iferror(lookup(J$41*12,$D$61:$DS$61,$D$63:$DS$63),"") -> 184 | K42: =iferror(lookup(K$41*12,$D$61:$DS$61,$D$63:$DS$63),"") -> 184 | ... M42: =iferror(lookup(M$41*12,$D$61:$DS$61,$D$63:$DS$63),"") -> 184
B43: Year End Offline Units | C43: 0 | D43: =iferror(lookup(D$41*12,$D$61:$DS$61,$D$64:$DS$64),"") -> 3 | E43: =iferror(lookup(E$41*12,$D$61:$DS$61,$D$64:$DS$64),"") -> 0 | F43: =iferror(lookup(F$41*12,$D$61:$DS$61,$D$64:$DS$64),"") -> 0 | G43: =iferror(lookup(G$41*12,$D$61:$DS$61,$D$64:$DS$64),"") -> 0 | H43: =iferror(lookup(H$41*12,$D$61:$DS$61,$D$64:$DS$64),"") -> 0 | I43: =iferror(lookup(I$41*12,$D$61:$DS$61,$D$64:$DS$64),"") -> 0 | J43: =iferror(lookup(J$41*12,$D$61:$DS$61,$D$64:$DS$64),"") -> 0 | K43: =iferror(lookup(K$41*12,$D$61:$DS$61,$D$64:$DS$64),"") -> 0 | ... M43: =iferror(lookup(M$41*12,$D$61:$DS$61,$D$64:$DS$64),"") -> 0
B44: Total Renovated Units | C44: 0 | D44: =iferror(lookup(D$41*12,$D$61:$DS$61,$D$65:$DS$65),"") -> 24 | E44: =iferror(lookup(E$41*12,$D$61:$DS$61,$D$65:$DS$65),"") -> 49 | F44: =iferror(lookup(F$41*12,$D$61:$DS$61,$D$65:$DS$65),"") -> 49 | G44: =iferror(lookup(G$41*12,$D$61:$DS$61,$D$65:$DS$65),"") -> 49 | H44: =iferror(lookup(H$41*12,$D$61:$DS$61,$D$65:$DS$65),"") -> 49 | I44: =iferror(lookup(I$41*12,$D$61:$DS$61,$D$65:$DS$65),"") -> 49 | J44: =iferror(lookup(J$41*12,$D$61:$DS$61,$D$65:$DS$65),"") -> 49 | K44: =iferror(lookup(K$41*12,$D$61:$DS$61,$D$65:$DS$65),"") -> 49 | ... M44: =iferror(lookup(M$41*12,$D$61:$DS$61,$D$65:$DS$65),"") -> 49
B45: Year End Occupancy % (Excl Offline Units) | C45: ='Historical Financials'!C7 -> 0.91847826 | D45: =iferror(lookup(D$41*12,$D$61:$DS$61,$D$66:$DS$66),"") -> 0.92 | E45: =iferror(lookup(E$41*12,$D$61:$DS$61,$D$66:$DS$66),"") -> 0.92 | F45: =iferror(lookup(F$41*12,$D$61:$DS$61,$D$66:$DS$66),"") -> 0.93 | G45: =iferror(lookup(G$41*12,$D$61:$DS$61,$D$66:$DS$66),"") -> 0.93 | H45: =iferror(lookup(H$41*12,$D$61:$DS$61,$D$66:$DS$66),"") -> 0.93 | I45: =iferror(lookup(I$41*12,$D$61:$DS$61,$D$66:$DS$66),"") -> 0.93 | J45: =iferror(lookup(J$41*12,$D$61:$DS$61,$D$66:$DS$66),"") -> 0.93 | K45: =iferror(lookup(K$41*12,$D$61:$DS$61,$D$66:$DS$66),"") -> 0.93 | ... M45: =iferror(lookup(M$41*12,$D$61:$DS$61,$D$66:$DS$66),"") -> 0.93
B46: Loss to Lease % | C46: =iferror(-C50/C49,"") -> 0.071881657 | D46: =iferror(-D50/D49,"") -> 0.061749222 | E46: =iferror(-E50/E49,"") -> 0.044981851 | F46: =iferror(-F50/F49,"") -> 0.041006083 | G46: =iferror(-G50/G49,"") -> 0.041006083 | H46: =iferror(-H50/H49,"") -> 0.041006083 | I46: =iferror(-I50/I49,"") -> 0.041006083 | J46: =iferror(-J50/J49,"") -> 0.041006083 | ... M46: =iferror(-M50/M49,"") -> 0.041006083
...

Sheet Expenses
M2: Property Expenses
B3: ='Property Summary'!B3 -> Phoenix, AZ | M3: ='Property Summary'!I3 -> Wind River Group
B5: Per Unit Analysis | C5: T-12 | D5: T-12 Per Unit | E5: 1 | F5: 1 | H5: Payroll Assumptions | I5: Hourly | J5: Wage | K5: 0.3 | L5: Total
B6: Total General & Admin | C6: ='Historical Financials'!C21 -> 126768.37 | D6: =iferror(C6/'Unit Mix & Comps'!$D$34,"") -> 688.95853 | E6: 695 | F6: =iferror(E6*'Unit Mix & Comps'!$D$34,"") -> 127880 | H6: Manager | I6: 35 | J6: =iferror(I6*52*40,"") -> 72800 | K6: =iferror(J6*$K$5,"") -> 21840 | L6: =iferror(sum(J6:K6),"") -> 94640
B7: Total Payroll | C7: ='Historical Financials'!C22 -> 324615.54 | D7: =iferror(C7/'Unit Mix & Comps'!$D$34,"") -> 1764.2149 | E7: =L12 -> 1763.4783 | F7: =iferror(E7*'Unit Mix & Comps'!$D$34,"") -> 324480 | H7: Asst Manager | I7: 30 | J7: =iferror(I7*52*40,"") -> 62400 | K7: =iferror(J7*$K$5,"") -> 18720 | L7: =iferror(sum(J7:K7),"") -> 81120
B8: Total Leasing & Marketing | C8: ='Historical Financials'!C23 -> 86807.36 | D8: =iferror(C8/'Unit Mix & Comps'!$D$34,"") -> 471.77913 | E8: 475 | F8: =iferror(E8*'Unit Mix & Comps'!$D$34,"") -> 87400 | H8: Maintenance | I8: 32.5 | J8: =iferror(I8*52*40,"") -> 67600 | K8: =iferror(J8*$K$5,"") -> 20280 | L8: =iferror(sum(J8:K8),"") -> 87880
B9: Total Utilities | C9: ='Historical Financials'!C24 -> 262578.11 | D9: =iferror(C9/'Unit Mix & Comps'!$D$34,"") -> 1427.0549 | E9: 1440 | F9: =iferror(E9*'Unit Mix & Comps'!$D$34,"") -> 264960 | H9: Tech | I9: 22.5 | J9: =iferror(I9*52*40,"") -> 46800 | K9: =iferror(J9*$K$5,"") -> 14040 | L9: =iferror(sum(J9:K9),"") -> 60840
B10: Total Repairs & Maintenance | C10: ='Historical Financials'!C25 -> 55342.64 | D10: =iferror(C10/'Unit Mix & Comps'!$D$34,"") -> 300.77522 | E10: 305 | F10: =iferror(E10*'Unit Mix & Comps'!$D$34,"") -> 56120 | H10: Asst Tech | I10: 0 | J10: =iferror(I10*52*20,"") -> 0 | K10: =iferror(J10*$K$5,"") -> 0 | L10: =iferror(sum(J10:K10),"") -> 0
B11: Total HOA Assessments | C11: ='Historical Financials'!C26 -> 20329.82 | D11: =iferror(C11/'Unit Mix & Comps'!$D$34,"") -> 110.48815 | E11: 115 | F11: =iferror(E11*'Unit Mix & Comps'!$D$34,"") -> 21160 | H11: Total | J11: =iferror(sum(J6:J10),"") -> 249600 | K11: =iferror(sum(K6:K10),"") -> 74880 | L11: =iferror(sum(L6:L10),"") -> 324480
B12: Total Turnover Expense | C12: ='Historical Financials'!C27 -> 22404.11 | D12: =iferror(C12/'Unit Mix & Comps'!$D$34,"") -> 121.76147 | E12: 125 | F12: =iferror(E12*'Unit Mix & Comps'!$D$34,"") -> 23000 | H12: Per unit | L12: =iferror(L11/'Unit Mix & Comps'!D34,"") -> 1763.4783
B13: Total Contract Services | C13: ='Historical Financials'!C28 -> 46032.26 | D13: =iferror(C13/'Unit Mix & Comps'!$D$34,"") -> 250.17533 | E13: 255 | F13: =iferror(E13*'Unit Mix & Comps'!$D$34,"") -> 46920
B14: Total Insurance Expense | C14: ='Historical Financials'!C29 -> 53468.94 | D14: =iferror(C14/'Unit Mix & Comps'!$D$34,"") -> 290.59207 | E14: 295 | F14: =iferror(E14*'Unit Mix & Comps'!$D$34,"") -> 54280
B15: Total Property Taxes | C15: ='Historical Financials'!C30 -> 142164.14 | D15: =iferror(C15/'Unit Mix & Comps'!$D$34,"") -> 772.6312 | E15: =iferror(F15/'Unit Mix & Comps'!$D$34,"") -> 811.26196 | F15: =iferror(if(I26="Manual Override",I24,I23),"") -> 149272.2
B16: Total Management Fees | C16: ='Historical Financials'!C31 -> 104943.81 | D16: =iferror(C16/'Unit Mix & Comps'!$D$34,"") -> 570.34679 | E16: =iferror(F16/'Unit Mix & Comps'!$D$34,"") -> 555.87538 | F16: =D42 -> 102281.07
B17: Total Operating Expenses | C17: ='Historical Financials'!C32 -> 1245455.1 | D17: =iferror(C17/'Unit Mix & Comps'!$D$34,"") -> 6768.7777 | E17: =iferror(sum(E6:E16),"") -> 6835.6156 | F17: =iferror(E17*'Unit Mix & Comps'!$D$34,"") -> 1257753.3
B19: Expense Growth Assumptions | H19: Property Taxes Assessment
B20: Annual Insurance Expense Growth | C20: 0.01 | H20: Purchase Price | I20: ='Project Budget'!G8 -> 36500000
B21: Annual Payroll Expense Growth | C21: 0.025 | H21: Assessed Value (% of Purchase Price) | I21: 0.4
B22: Annual Repairs and Maintenance Expense Growth | C22: 0.025 | H22: Tax Rate (% of Assessed Value) | I22: 0.0317
B23: Tax Reassessment Growth | C23: 0.05 | H23: Assessed Year 1 Property Tax | I23: =iferror(I20*I21*I22,"") -> 462820
B24: Annual Tax Expense Growth | C24: 0.01 | H24: Manual Override | I24: =142164*1.05 -> 149272.2
B25: All Other Expense Growth | C25: 0.025 | H25: Years Between Reassessment | I25: 1 | J25: First Reassessment Year | K25: 2
B26: Property Management Fee (% of Total Revenue) | C26: 0.03 | H26: Method Used | I26: Manual Override | J26: Must be greater than 1
B28: Projected Annual Expenses
C31: T-12 | D31: 1 | E31: 2 | F31: 3 | G31: 4 | H31: 5 | I31: 6 | J31: 7 | K31: 8 | L31: 9 | M31: 10
B32: Total General & Admin | C32: ='Historical Financials'!C21 -> 126768.37 | D32: =iferror(F6,"") -> 127880 | E32: =iferror(D32*(1+$C$25),"") -> 131077 | F32: =iferror(E32*(1+$C$25),"") -> 134353.92 | G32: =iferror(F32*(1+$C$25),"") -> 137712.77 | H32: =iferror(G32*(1+$C$25),"") -> 141155.59 | I32: =iferror(H32*(1+$C$25),"") -> 144684.48 | J32: =iferror(I32*(1+$C$25),"") -> 148301.59 | K32: =iferror(J32*(1+$C$25),"") -> 152009.13 | L32: =iferror(K32*(1+$C$25),"") -> 155809.36 | M32: =iferror(L32*(1+$C$25),"") -> 159704.6
B33: Total Payroll | C33: ='Historical Financials'!C22 -> 324615.54 | D33: =iferror(F7,"") -> 324480 | E33: =iferror(D33*(1+$C$21),"") -> 332592 | F33: =iferror(E33*(1+$C$21),"") -> 340906.8 | G33: =iferror(F33*(1+$C$21),"") -> 349429.47 | H33: =iferror(G33*(1+$C$21),"") -> 358165.21 | I33: =iferror(H33*(1+$C$21),"") -> 367119.34 | J33: =iferror(I33*(1+$C$21),"") -> 376297.32 | K33: =iferror(J33*(1+$C$21),"") -> 385704.75 | L33: =iferror(K33*(1+$C$21),"") -> 395347.37 | M33: =iferror(L33*(1+$C$21),"") -> 405231.06
B34: Total Leasing & Marketing | C34: ='Historical Financials'!C23 -> 86807.36 | D34: =iferror(F8,"") -> 87400 | E34: =iferror(D34*(1+$C$25),"") -> 89585 | F34: =iferror(E34*(1+$C$25),"") -> 91824.625 | G34: =iferror(F34*(1+$C$25),"") -> 94120.241 | H34: =iferror(G34*(1+$C$25),"") -> 96473.247 | I34: =iferror(H34*(1+$C$25),"") -> 98885.078 | J34: =iferror(I34*(1+$C$25),"") -> 101357.2 | K34: =iferror(J34*(1+$C$25),"") -> 103891.13 | L34: =iferror(K34*(1+$C$25),"") -> 106488.41 | M34: =iferror(L34*(1+$C$25),"") -> 109150.62
B35: Total Utilities | C35: ='Historical Financials'!C24 -> 262578.11 | D35: =iferror(F9,"") -> 264960 | E35: =iferror(D35*(1+$C$25),"") -> 271584 | F35: =iferror(E35*(1+$C$25),"") -> 278373.6 | G35: =iferror(F35*(1+$C$25),"") -> 285332.94 | H35: =iferror(G35*(1+$C$25),"") -> 292466.26 | I35: =iferror(H35*(1+$C$25),"") -> 299777.92 | J35: =iferror(I35*(1+$C$25),"") -> 307272.37 | K35: =iferror(J35*(1+$C$25),"") -> 314954.18 | L35: =iferror(K35*(1+$C$25),"") -> 322828.03 | M35: =iferror(L35*(1+$C$25),"") -> 330898.73
B36: Total Repairs & Maintenance | C36: ='Historical Financials'!C25 -> 55342.64 | D36: =iferror(F10,"") -> 56120 | E36: =iferror(D36*(1+$C$22),"") -> 57523 | F36: =iferror(E36*(1+$C$22),"") -> 58961.075 | G36: =iferror(F36*(1+$C$22),"") -> 60435.102 | H36: =iferror(G36*(1+$C$22),"") -> 61945.979 | I36: =iferror(H36*(1+$C$22),"") -> 63494.629 | J36: =iferror(I36*(1+$C$22),"") -> 65081.995 | K36: =iferror(J36*(1+$C$22),"") -> 66709.045 | L36: =iferror(K36*(1+$C$22),"") -> 68376.771 | M36: =iferror(L36*(1+$C$22),"") -> 70086.19
B37: Total Supply Expense | C37: ='Historical Financials'!C26 -> 20329.82 | D37: =iferror(F11,"") -> 21160 | E37: =iferror(D37*(1+$C$25),"") -> 21689 | F37: =iferror(E37*(1+$C$25),"") -> 22231.225 | G37: =iferror(F37*(1+$C$25),"") -> 22787.006 | H37: =iferror(G37*(1+$C$25),"") -> 23356.681 | I37: =iferror(H37*(1+$C$25),"") -> 23940.598 | J37: =iferror(I37*(1+$C$25),"") -> 24539.113 | K37: =iferror(J37*(1+$C$25),"") -> 25152.591 | L37: =iferror(K37*(1+$C$25),"") -> 25781.405 | M37: =iferror(L37*(1+$C$25),"") -> 26425.94
B38: Total Turnover Expense | C38: ='Historical Financials'!C27 -> 22404.11 | D38: =iferror(F12,"") -> 23000 | E38: =iferror(D38*(1+$C$25),"") -> 23575 | F38: =iferror(E38*(1+$C$25),"") -> 24164.375 | G38: =iferror(F38*(1+$C$25),"") -> 24768.484 | H38: =iferror(G38*(1+$C$25),"") -> 25387.696 | I38: =iferror(H38*(1+$C$25),"") -> 26022.389 | J38: =iferror(I38*(1+$C$25),"") -> 26672.949 | K38: =iferror(J38*(1+$C$25),"") -> 27339.772 | L38: =iferror(K38*(1+$C$25),"") -> 28023.267 | M38: =iferror(L38*(1+$C$25),"") -> 28723.848
B39: Total Contract Services | C39: ='Historical Financials'!C28 -> 46032.26 | D39: =iferror(F13,"") -> 46920 | E39: =iferror(D39*(1+$C$25),"") -> 48093 | F39: =iferror(E39*(1+$C$25),"") -> 49295.325 | G39: =iferror(F39*(1+$C$25),"") -> 50527.708 | H39: =iferror(G39*(1+$C$25),"") -> 51790.901 | I39: =iferror(H39*(1+$C$25),"") -> 53085.673 | J39: =iferror(I39*(1+$C$25),"") -> 54412.815 | K39: =iferror(J39*(1+$C$25),"") -> 55773.136 | L39: =iferror(K39*(1+$C$25),"") -> 57167.464 | M39: =iferror(L39*(1+$C$25),"") -> 58596.651
B40: Total Insurance Expense | C40: ='Historical Financials'!C29 -> 53468.94 | D40: =iferror(F14,"") -> 54280 | E40: =iferror(D40*(1+$C$20),"") -> 54822.8 | F40: =iferror(E40*(1+$C$20),"") -> 55371.028 | G40: =iferror(F40*(1+$C$20),"") -> 55924.738 | H40: =iferror(G40*(1+$C$20),"") -> 56483.986 | I40: =iferror(H40*(1+$C$20),"") -> 57048.826 | J40: =iferror(I40*(1+$C$20),"") -> 57619.314 | K40: =iferror(J40*(1+$C$20),"") -> 58195.507 | L40: =iferror(K40*(1+$C$20),"") -> 58777.462 | M40: =iferror(L40*(1+$C$20),"") -> 59365.237
B41: Total Property Taxes | C41: ='Historical Financials'!C30 -> 142164.14 | D41: =iferror(F15,"") -> 149272.2 | E41: =iferror(if(E45="Yes",D41*(1+$C$23),D41*(1+$C$24)),"") -> 156735.81 | F41: =iferror(if(F45="Yes",E41*(1+$C$23),E41*(1+$C$24)),"") -> 164572.6 | G41: =iferror(if(G45="Yes",F41*(1+$C$23),F41*(1+$C$24)),"") -> 172801.23 | H41: =iferror(if(H45="Yes",G41*(1+$C$23),G41*(1+$C$24)),"") -> 181441.29 | I41: =iferror(if(I45="Yes",H41*(1+$C$23),H41*(1+$C$24)),"") -> 190513.36 | J41: =iferror(if(J45="Yes",I41*(1+$C$23),I41*(1+$C$24)),"") -> 200039.02 | K41: =iferror(if(K45="Yes",J41*(1+$C$23),J41*(1+$C$24)),"") -> 202039.41 | L41: =iferror(if(L45="Yes",K41*(1+$C$23),K41*(1+$C$24)),"") -> 204059.81 | M41: =iferror(if(M45="Yes",L41*(1+$C$23),L41*(1+$C$24)),"") -> 206100.41
B42: Total Management Fees | C42: ='Historical Financials'!C31 -> 104943.81 | D42: =iferror(lookup(D$31,Revenue!$D$41:$M$41,Revenue!$D$58:$M$58)*$C$26,"") -> 102281.07 | E42: =iferror(lookup(E$31,Revenue!$D$41:$M$41,Revenue!$D$58:$M$58)*$C$26,"") -> 107659.79 | F42: =iferror(lookup(F$31,Revenue!$D$41:$M$41,Revenue!$D$58:$M$58)*$C$26,"") -> 113762 | G42: =iferror(lookup(G$31,Revenue!$D$41:$M$41,Revenue!$D$58:$M$58)*$C$26,"") -> 117465.61 | H42: =iferror(lookup(H$31,Revenue!$D$41:$M$41,Revenue!$D$58:$M$58)*$C$26,"") -> 121293.29 | I42: =iferror(lookup(I$31,Revenue!$D$41:$M$41,Revenue!$D$58:$M$58)*$C$26,"") -> 125249.26 | J42: =iferror(lookup(J$31,Revenue!$D$41:$M$41,Revenue!$D$58:$M$58)*$C$26,"") -> 129337.9 | K42: =iferror(lookup(K$31,Revenue!$D$41:$M$41,Revenue!$D$58:$M$58)*$C$26,"") -> 133563.75 | ... M42: =iferror(lookup(M$31,Revenue!$D$41:$M$41,Revenue!$D$58:$M$58)*$C$26,"") -> 142445.94
B43: Total Operating Expenses | C43: ='Historical Financials'!C32 -> 1245455.1 | D43: =iferror(sum(D32:D42),"") -> 1257753.3 | E43: =iferror(sum(E32:E42),"") -> 1294936.4 | F43: =iferror(sum(F32:F42),"") -> 1333816.6 | G43: =iferror(sum(G32:G42),"") -> 1371305.3 | H43: =iferror(sum(H32:H42),"") -> 1409960.1 | I43: =iferror(sum(I32:I42),"") -> 1449821.5 | J43: =iferror(sum(J32:J42),"") -> 1490931.6 | K43: =iferror(sum(K32:K42),"") -> 1525332.4 | ... M43: =iferror(sum(M32:M42),"") -> 1596729.2
B44: Expense Ratio | C44: ='Historical Financials'!C33 -> 0.36493849 | D44: =iferror(D43/lookup(D$31,Revenue!$D$41:$M$41,Revenue!$D$58:$M$58),"") -> 0.36891086 | E44: =iferror(E43/lookup(E$31,Revenue!$D$41:$M$41,Revenue!$D$58:$M$58),"") -> 0.36084124 | F44: =iferror(F43/lookup(F$31,Revenue!$D$41:$M$41,Revenue!$D$58:$M$58),"") -> 0.35173869 | G44: =iferror(G43/lookup(G$31,Revenue!$D$41:$M$41,Revenue!$D$58:$M$58),"") -> 0.350223 | H44: =iferror(H43/lookup(H$31,Revenue!$D$41:$M$41,Revenue!$D$58:$M$58),"") -> 0.34873161 | I44: =iferror(I43/lookup(I$31,Revenue!$D$41:$M$41,Revenue!$D$58:$M$58),"") -> 0.3472647 | J44: =iferror(J43/lookup(J$31,Revenue!$D$41:$M$41,Revenue!$D$58:$M$58),"") -> 0.34582243 | K44: =iferror(K43/lookup(K$31,Revenue!$D$41:$M$41,Revenue!$D$58:$M$58),"") -> 0.34260772 | ... M44: =iferror(M43/lookup(M$31,Revenue!$D$41:$M$41,Revenue!$D$58:$M$58),"") -> 0.33628109
B45: Reassessment Year | D45: =iferror(ifs(D$31=$K$25,"Yes",$K$25+($I$25*1)=D$31,"Yes",$K$25+($I$25*2)=D$31,"Yes",$K$25+($I$25*3)=D$31,"Yes",$K$25+($I$25*4)=D$31,"Yes",$K$25+($I$25*5)=D$31,"Yes"),"No") -> No | E45: =iferror(ifs(E$31=$K$25,"Yes",$K$25+($I$25*1)=E$31,"Yes",$K$25+($I$25*2)=E$31,"Yes",$K$25+($I$25*3)=E$31,"Yes",$K$25+($I$25*4)=E$31,"Yes",$K$25+($I$25*5)=E$31,"Yes"),"No") -> Yes | F45: =iferror(ifs(F$31=$K$25,"Yes",$K$25+($I$25*1)=F$31,"Yes",$K$25+($I$25*2)=F$31,"Yes",$K$25+($I$25*3)=F$31,"Yes",$K$25+($I$25*4)=F$31,"Yes",$K$25+($I$25*5)=F$31,"Yes"),"No") -> Yes | G45: =iferror(ifs(G$31=$K$25,"Yes",$K$25+($I$25*1)=G$31,"Yes",$K$25+($I$25*2)=G$31,"Yes",$K$25+($I$25*3)=G$31,"Yes",$K$25+($I$25*4)=G$31,"Yes",$K$25+($I$25*5)=G$31,"Yes"),"No") -> Yes | H45: =iferror(ifs(H$31=$K$25,"Yes",$K$25+($I$25*1)=H$31,"Yes",$K$25+($I$25*2)=H$31,"Yes",$K$25+($I$25*3)=H$31,"Yes",$K$25+($I$25*4)=H$31,"Yes",$K$25+($I$25*5)=H$31,"Yes"),"No") -> Yes | I45: =iferror(ifs(I$31=$K$25,"Yes",$K$25+($I$25*1)=I$31,"Yes",$K$25+($I$25*2)=I$31,"Yes",$K$25+($I$25*3)=I$31,"Yes",$K$25+($I$25*4)=I$31,"Yes",$K$25+($I$25*5)=I$31,"Yes"),"No") -> Yes | J45: =iferror(ifs(J$31=$K$25,"Yes",$K$25+($I$25*1)=J$31,"Yes",$K$25+($I$25*2)=J$31,"Yes",$K$25+($I$25*3)=J$31,"Yes",$K$25+($I$25*4)=J$31,"Yes",$K$25+($I$25*5)=J$31,"Yes"),"No") -> Yes | K45: =iferror(ifs(K$31=$K$25,"Yes",$K$25+($I$25*1)=K$31,"Yes",$K$25+($I$25*2)=K$31,"Yes",$K$25+($I$25*3)=K$31,"Yes",$K$25+($I$25*4)=K$31,"Yes",$K$25+($I$25*5)=K$31,"Yes"),"No") -> No | ... M45: =iferror(ifs(M$31=$K$25,"Yes",$K$25+($I$25*1)=M$31,"Yes",$K$25+($I$25*2)=M$31,"Yes",$K$25+($I$25*3)=M$31,"Yes",$K$25+($I$25*4)=M$31,"Yes",$K$25+($I$25*5)=M$31,"Yes"),"No") -> No

Sheet CapEx
K2: CapEx Budget
B3: ='Property Summary'!B3 -> Phoenix, AZ | K3: ='Property Summary'!I3 -> Wind River Group
B5: Unit Renovations | J5: Item | K5: Cost
B6: Unit Type / SF | C6: Available Units | D6: Renovation Units | E6: Cost Per Unit | F6: Total Cost | G6: Rent Premium after Renovation | H6: Renovation ROI (Increase over Current) | J6: Black Appliances | K6: 1800
